<!-- models/spinner_bot/model.sdf -->
<sdf version="1.6">
  <model name="spinner_bot">
    <include>
      <uri>model://ground_plane</uri>
    </include>
    <include>
      <uri>model://sun</uri>
    </include>

    <link name="base_link">
      <pose>0 0 0.1 0 0 0</pose>
      <inertial>
        <mass>5.0</mass>
        <inertia>
          <ixx>0.1</ixx>
          <iyy>0.1</iyy>
          <izz>0.1</izz>
        </inertia>
      </inertial>
      <collision name="collision">
        <geometry>
          <box>
            <size>0.5 0.5 0.2</size>
          </box>
        </geometry>
      </collision>
      <visual name="visual">
        <geometry>
          <box>
            <size>0.5 0.5 0.2</size>
          </box>
        </geometry>
      </visual>
    </link>

    <link name="spinner">
      <pose>0 0 0.2 0 0 0</pose>
      <inertial>
        <mass>1.0</mass>
        <inertia>
          <ixx>0.02</ixx>
          <iyy>0.02</iyy>
          <izz>0.01</izz>
        </inertia>
      </inertial>
      <collision name="collision">
        <geometry>
          <cylinder>
            <radius>0.3</radius>
            <length>0.02</length>
          </cylinder>
        </geometry>
      </collision>
      <visual name="visual">
        <geometry>
          <cylinder>
            <radius>0.3</radius>
            <length>0.02</length>
          </cylinder>
        </geometry>
      </visual>
    </link>

    <joint name="spinner_joint" type="revolute">
      <parent>base_link</parent>
      <child>spinner</child>
      <axis>
        <xyz>0 0 1</xyz>
        <limit>
          <effort>10</effort>
          <velocity>20</velocity>
        </limit>
      </axis>
    </joint>

    <!-- Plugin to spin the spinner -->
    <plugin name="spinner_control" filename="libgazebo_ros_joint_force.so">
      <joint_name>spinner_joint</joint_name>
      <force>1.0</force>
    </plugin>
  </model>
</sdf>
