<?xml version="1.0"?>
<robot name="battlebot_1">

  <link name="base_link">
    <visual>
      <origin xyz="0 0 0.22" rpy="0 0 0"/>
      <geometry>
        <box size="1.3 0.9 0.3"/>
      </geometry>
      <material name="blue"><color rgba="0.2 0.4 0.8 1"/></material>
    </visual>
    <collision>
      <origin xyz="0 0 0.22" rpy="0 0 0"/>
      <geometry>
        <box size="1.3 0.9 0.3"/>
      </geometry>
    </collision>
    <inertial>
      <origin xyz="0 0 0.22" rpy="0 0 0"/>
      <mass value="15.0"/>
      <inertia ixx="5.0" ixy="0.0" ixz="0.0" iyy="5.0" iyz="0.0" izz="5.0"/>
    </inertial>
  </link>

  <link name="left_wheel_link">
    <visual>
      <origin rpy="1.5707 0 0"/>
      <geometry>
        <cylinder radius="0.24" length="0.1"/>
      </geometry>
      <material name="black">
        <color rgba="0.1 0.1 0.1 1"/>
      </material>
    </visual>
    <collision>
      <origin rpy="1.5707 0 0"/>
      <geometry>
        <cylinder radius="0.24" length="0.1"/>
      </geometry>
    </collision>
    <inertial>
      <mass value="1.0"/>
      <inertia ixx="0.01" ixy="0.0" ixz="0.0" iyy="0.01" iyz="0.0" izz="0.01"/>
    </inertial>
  </link>

  <link name="right_wheel_link">
    <visual>
      <origin rpy="1.5707 0 0"/>
      <geometry>
        <cylinder radius="0.24" length="0.1"/>
      </geometry>
      <material name="black"/>
    </visual>
    <collision>
      <origin rpy="1.5707 0 0"/>
      <geometry>
        <cylinder radius="0.24" length="0.1"/>
      </geometry>
    </collision>
    <inertial>
      <mass value="1.0"/>
      <inertia ixx="0.01" ixy="0.0" ixz="0.0" iyy="0.01" iyz="0.0" izz="0.01"/>
    </inertial>
  </link>

  <joint name="left_wheel_joint" type="continuous">
    <parent link="base_link"/>
    <child link="left_wheel_link"/>
    <origin xyz="0.0 0.525 0.2" rpy="0 0 0"/>
    <axis xyz="0 1 0"/>
  </joint>

  <joint name="right_wheel_joint" type="continuous">
    <parent link="base_link"/>
    <child link="right_wheel_link"/>
    <origin xyz="0.0 -0.525 0.2" rpy="0 0 0"/>
    <axis xyz="0 1 0"/>
  </joint>

  <gazebo>
    <plugin name="diff_drive" filename="libgazebo_ros_diff_drive.so">
      <ros>
        <namespace>/battlebot_1</namespace>
      </ros>
      <left_joint>left_wheel_joint</left_joint>
      <right_joint>right_wheel_joint</right_joint>
      <wheel_separation>1.05</wheel_separation>
      <wheel_diameter>0.48</wheel_diameter>
      <max_wheel_torque>200</max_wheel_torque>
      <command_topic>cmd_vel</command_topic>
      <odometry_topic>odom</odometry_topic>
      <odometry_frame>odom</odometry_frame>
      <robot_base_frame>base_link</robot_base_frame>
    </plugin>
  </gazebo>

  <gazebo reference="base_link">
    <kp>1000000.0</kp>
    <kd>100.0</kd>
    <minDepth>0.001</minDepth>
    <maxVel>1.0</maxVel>
    <material>Gazebo/Blue</material>

    <sensor name="contact_sensor" type="contact">
      <always_on>true</always_on>
      <update_rate>30</update_rate>
      <contact>
        <collision>base_link_collision</collision>
      </contact>
      <plugin name="gazebo_ros_bumper" filename="libgazebo_ros_bumper.so">
        <ros>
          <namespace>/battlebot_1</namespace>
          <remapping>bumper_states:=contact</remapping>
        </ros>
        <frame_name>base_link</frame_name>
      </plugin>
    </sensor>

    <sensor name="imu_sensor" type="imu">
      <always_on>true</always_on>
      <update_rate>30</update_rate> <imu>
        <angular_velocity>
          <x><noise type="gaussian"><mean>0.0</mean><stddev>0.001</stddev></noise></x>
          <y><noise type="gaussian"><mean>0.0</mean><stddev>0.001</stddev></noise></y>
          <z><noise type="gaussian"><mean>0.0</mean><stddev>0.001</stddev></noise></z>
        </angular_velocity>
        <linear_acceleration>
          <x><noise type="gaussian"><mean>0.0</mean><stddev>0.01</stddev></noise></x>
          <y><noise type="gaussian"><mean>0.0</mean><stddev>0.01</stddev></noise></y>
          <z><noise type="gaussian"><mean>0.0</mean><stddev>0.01</stddev></noise></z>
        </linear_acceleration>
      </imu>
        <plugin name="gazebo_ros_imu_sensor" filename="libgazebo_ros_imu_sensor.so">
          <ros>
            <namespace>/battlebot_1</namespace>
            <remapping>~/out:=imu</remapping>
          </ros>
          <initial_orientation_as_reference>false</initial_orientation_as_reference>
        </plugin>
    </sensor>
  </gazebo>
</robot>